<?xml version="1.0" encoding="utf-8"?>
<robot name="robot_1">

    <!-- Define the base_footprint link -->
    <link name="base_footprint">
        <!-- Define inertial, visual, and collision properties if needed -->
    </link>

    <!-- Define the base_link link -->
    <link name="base_link">
        <inertial>
            <origin xyz="0 0 0" rpy="0 0 0"/>
            <mass value="2.79660707993412"/>
            <inertia ixx="0.0104497675683349" ixy="0" ixz="0" iyy="0.0104638880534191" iyz="0" izz="0.018631250518789"/>
        </inertial>
        <visual>
            <origin xyz="0 0 0" rpy="0 0 0"/>
            <geometry>
                <mesh filename="package://robot_1/meshes/base_link.STL"/>
            </geometry>
            <material name="">
                <color rgba="0.792156862745098 0.819607843137255 0.933333333333333 1"/>
            </material>
        </visual>
        <collision>
            <origin xyz="0 0 0" rpy="0 0 0"/>
            <geometry>
                <mesh filename="package://robot_1/meshes/base_link.STL"/>
            </geometry>
        </collision>
    </link>

    <!-- Define the base_joint -->
    <joint name="base_joint" type="fixed">
        <origin xyz="0 0 0" rpy="0 0 0"/>
        <parent link="base_footprint"/>
        <child link="base_link"/>
        <axis xyz="0 0 1"/>
    </joint>

    <!-- Define Front_Left link -->
    <link name="Front_Left">
        <inertial>
            <origin xyz="0 0 0" rpy="0 0 0"/>
            <mass value="0.0853884883245706"/>
            <inertia ixx="2.58181109779992E-05" ixy="0" ixz="0" iyy="2.58181109779992E-05" iyz="0" izz="3.81728954311654E-05"/>
        </inertial>
        <visual>
            <origin xyz="0 0 0" rpy="0 0 0"/>
            <geometry>
                <mesh filename="package://robot_1/meshes/Front_Left.STL"/>
            </geometry>
            <material name="">
                <color rgba="0.792156862745098 0.819607843137255 0.933333333333333 1"/>
            </material>
        </visual>
        <collision>
            <origin xyz="0 0 0" rpy="0 0 0"/>
            <geometry>
                <mesh filename="package://robot_1/meshes/Front_Left.STL"/>
            </geometry>
        </collision>
    </link>

    <!-- Define FrontLeft joint -->
    <joint name="FrontLeft" type="continuous">
        <origin xyz="0.056 0.13 -0.06" rpy="-1.5707963267949 0 0"/>
        <parent link="base_link"/>
        <child link="Front_Left"/>
        <axis xyz="0 0 -1"/>
        <limit effort="10" velocity="10"/>
        <dynamics damping="0.1" friction="0.1"/>
    </joint>

    <!-- Define Back_Left link -->
    <link name="Back_Left">
        <inertial>
            <origin xyz="0 0 0" rpy="0 0 0"/>
            <mass value="0.0853884883245706"/>
            <inertia ixx="2.58181109779992E-05" ixy="0" ixz="0" iyy="2.58181109779992E-05" iyz="0" izz="3.81728954311654E-05"/>
        </inertial>
        <visual>
            <origin xyz="0 0 0" rpy="0 0 0"/>
            <geometry>
                <mesh filename="package://robot_1/meshes/Back_Left.STL"/>
            </geometry>
            <material name="">
                <color rgba="0.792156862745098 0.819607843137255 0.933333333333333 1"/>
            </material>
        </visual>
        <collision>
            <origin xyz="0 0 0" rpy="0 0 0"/>
            <geometry>
                <mesh filename="package://robot_1/meshes/Back_Left.STL"/>
            </geometry>
        </collision>
    </link>

    <!-- Define BackLeft joint -->
    <joint name="BackLeft" type="continuous">
        <origin xyz="-0.056 0.13 -0.06" rpy="-1.5707963267949 0 0"/>
        <parent link="base_link"/>
        <child link="Back_Left"/>
        <axis xyz="0 0 -1"/>
        <limit effort="10" velocity="10"/>
        <dynamics damping="0.1" friction="0.1"/>
    </joint>

    <!-- Define Front_Right link -->
    <link name="Front_Right">
        <inertial>
            <origin xyz="0 0 0" rpy="0 0 0"/>
            <mass value="0.0853884883245706"/>
            <inertia ixx="2.58181109779992E-05" ixy="0" ixz="0" iyy="2.58181109779992E-05" iyz="0" izz="3.81728954311654E-05"/>
        </inertial>
        <visual>
            <origin xyz="0 0 0" rpy="0 0 0"/>
            <geometry>
                <mesh filename="package://robot_1/meshes/Front_Right.STL"/>
            </geometry>
            <material name="">
                <color rgba="0.792156862745098 0.819607843137255 0.933333333333333 1"/>
            </material>
        </visual>
        <collision>
            <origin xyz="0 0 0" rpy="0 0 0"/>
            <geometry>
                <mesh filename="package://robot_1/meshes/Front_Right.STL"/>
            </geometry>
        </collision>
    </link>

    <!-- Define FrontRight joint -->
    <joint name="FrontRight" type="continuous">
        <origin xyz="0.056 -0.13 -0.06" rpy="-1.5707963267949 0 0"/>
        <parent link="base_link"/>
        <child link="Front_Right"/>
        <axis xyz="0 0 1"/>
        <limit effort="10" velocity="10"/>
        <dynamics damping="0.1" friction="0.1"/>
    </joint>

    <!-- Define Back_Right link -->
    <link name="Back_Right">
        <inertial>
            <origin xyz="0 0 0" rpy="0 0 0"/>
            <mass value="0.0853884883245706"/>
            <inertia ixx="2.58181109779992E-05" ixy="0" ixz="0" iyy="2.58181109779992E-05" iyz="0" izz="3.81728954311654E-05"/>
        </inertial>
        <visual>
            <origin xyz="0 0 0" rpy="0 0 0"/>
            <geometry>
                <mesh filename="package://robot_1/meshes/Back_Right.STL"/>
            </geometry>
            <material name="">
                <color rgba="0.792156862745098 0.819607843137255 0.933333333333333 1"/>
            </material>
        </visual>
        <collision>
            <origin xyz="0 0 0" rpy="0 0 0"/>
            <geometry>
                <mesh filename="package://robot_1/meshes/Back_Right.STL"/>
            </geometry>
        </collision>
    </link>

    <!-- Define BackRight joint -->
    <joint name="BackRight" type="continuous">
        <origin xyz="-0.056 -0.13 -0.06" rpy="-1.5707963267949 0 0"/>
        <parent link="base_link"/>
        <child link="Back_Right"/>
        <axis xyz="0 0 1"/>
        <limit effort="10" velocity="10"/>
        <dynamics damping="0.1" friction="0.1"/>
    </joint>

    <!-- Gazebo plugin -->
    <gazebo>
        <plugin name="skid_steer_drive_controller" filename="libgazebo_ros_skid_steer_drive.so">
            <updateRate>100.0</updateRate>
            <robotNamespace>/</robotNamespace>
            <leftFrontJoint>FrontLeft</leftFrontJoint>
            <rightFrontJoint>FrontRight</rightFrontJoint>
            <leftRearJoint>BackLeft</leftRearJoint>
            <rightRearJoint>BackRight</rightRearJoint>
            <wheelSeparation>0.4</wheelSeparation>
            <wheelDiameter>0.215</wheelDiameter>
            <robotBaseFrame>base_link</robotBaseFrame>
            <torque>20</torque>
            <publishWheelTF>true</publishWheelTF>
            <publishWheelJointState>true</publishWheelJointState>
            <topicName>cmd_vel</topicName>
            <odometryTopic>/odom</odometryTopic>
            <odometryFrame>odom</odometryFrame>
            <broadcastTF>false</broadcastTF>
        </plugin>
    </gazebo>
  <!-- hokuyo -->
  <gazebo reference="hokuyo_link">
    <sensor type="gpu_ray" name="head_hokuyo_sensor">
      <pose>0 0 0 0 0 0</pose>
      <visualize>false</visualize>
      <update_rate>40</update_rate>
      <ray>
        <scan>
          <horizontal>
            <samples>720</samples>
            <resolution>1</resolution>
            <min_angle>-1.570796</min_angle>
            <max_angle>1.570796</max_angle>
          </horizontal>
        </scan>
        <range>
          <min>0.10</min>
          <max>30.0</max>
          <resolution>0.01</resolution>
        </range>
        <noise>
          <type>gaussian</type>
          <!-- Noise parameters based on published spec for Hokuyo laser
               achieving "+-30mm" accuracy at range < 10m.  A mean of 0.0m and
               stddev of 0.01m will put 99.7% of samples within 0.03m of the true
               reading. -->
          <mean>0.0</mean>
          <stddev>0.01</stddev>
        </noise>
      </ray>
      <plugin name="gazebo_ros_head_hokuyo_controller" filename="libgazebo_ros_gpu_laser.so">
        <topicName>/rrbot/laser/scan</topicName>
        <frameName>hokuyo_link</frameName>
      </plugin>
    </sensor>
  </gazebo>
</robot>
